<?xml version="1.0" encoding="utf-8"?>
<mujoco>
    <include file="shared_config.xml"></include>
    <worldbody>
        <include file="sawyer_xyz_base.xml"></include>
        <body name="obj0" pos="0 0.6 0.05">
            <geom name="objGeom0" type="box" pos="0 0 0" solimp="0.99 0.99 0.01"
                  size="0.025 0.025 0.025" rgba="0.0 1.0 0.0 1" solref="0.01 1"
                  contype="1" conaffinity="1" condim="4" 
            />
            <joint name="objGeom0_x" type="slide" pos="0 0 0" axis="1 0 0" range="-0.3 0.3" damping="100"/>
            <joint name="objGeom0_y" type="slide" pos="0 0 0" axis="0 1 0" range="-0.3 0.3" damping="100"/>
            <joint name="objGeom0_z" type="slide" pos="0 0 0" axis="0 0 1" range="0 0.1" damping="100"/>
            <inertial pos="0 0 0" mass="10" diaginertia="0.001 0.001 0.001"/>
        </body>

        <body name="obj1" pos="0 0.6 0.05">
            <geom name="objGeom1" type="box" pos="0 0 0" solimp="0.99 0.99 0.01"
                  size="0.025 0.025 0.025" rgba="1 0.5 1 1" solref="0.01 1"
                  contype="1" conaffinity="1" condim="4" 
            />
            <joint name="objGeom1_x" type="slide" pos="0 0 0" axis="1 0 0" range="-0.3 0.3" damping="100"/>
            <joint name="objGeom1_y" type="slide" pos="0 0 0" axis="0 1 0" range="-0.3 0.3" damping="100"/>
            <joint name="objGeom1_z" type="slide" pos="0 0 0" axis="0 0 1" range="-0 0.1" damping="100"/>
            <inertial pos="0 0 0" mass="10" diaginertia="0.001 0.001 0.001"/>
        </body>
      
      <body name="obj2" pos="0 0.6 0.05">
            <geom name="objGeom2" type="box" pos="0 0 0" solimp="0.99 0.99 0.01"
                  size="0.025 0.025 0.025" rgba="0 0.0 1 1" solref="0.01 1"
                  contype="1" conaffinity="1" condim="4" 
            />
            <joint name="objGeom2_x" type="slide" pos="0 0 0" axis="1 0 0" range="-0.3 0.3" damping="100"/>
            <joint name="objGeom2_y" type="slide" pos="0 0 0" axis="0 1 0" range="-0.3 0.3" damping="100"/>
            <joint name="objGeom2_z" type="slide" pos="0 0 0" axis="0 0 1" range="0 0.1" damping="100"/>
            <inertial pos="0 0 0" mass="10" diaginertia="0.001 0.001 0.001"/>
        </body>

        <body name="door" pos="0 0.9 0.05">
            <inertial diaginertia="0.0914 0.0522 0.0437" mass="2.4346" pos="0.0297 -0.0015 0" quat="0.7011 0 0 0.7131"></inertial>
            <joint armature="0.01" axis="0 0 1" damping="1" frictionloss="0.1" limited="true" name="door_hinge" pos="0.25 0 0" range="0 1.57" type="hinge"></joint>
            <geom condim="3" friction="1 1 1" size="0.2 0.05 0.25" type="box"></geom>
            <geom pos="0.2 0 0" size="0.05 0.05 0.25" type="box"></geom>
            <geom pos="-0.15 -0.065 -0.051" size="0.05 0.015 0.01" type="box"></geom>
            <geom pos="-0.15 -0.065 0.051" size="0.05 0.015 0.01" type="box"></geom>
            <geom pos="-0.15 -0.09 0" size="0.05 0.011 0.06" type="box"></geom>
            <geom pos="-0.15 -0.16 0" size="0.01 0.01 0.05" type="box" euler="0 -1.5708 0"></geom>
            <body name="latch" pos="-0.16 -0.065 0">
                <inertial diaginertia="0.0038 0.0036 0.0002" mass="0.4657" pos="0.0042 -0.001 0" quat="0.504 0.504 0.496 0.496"></inertial>
                <geom condim="1" size="0.15 0.01 0.0375" type="box"></geom>
                <geom pos="0.125 -0.03 0" size="0.01 0.01 0.02" type="box"></geom>
                <joint axis="1 0 0" frictionloss="0.1" limited="true" name="latch_joint" pos="0 0 0" range="0 0.15" type="slide"></joint>
            </body>
        </body>

        <camera mode="fixed" name="cam0" pos="-0.0 1.35 0.8" quat="0.924 -0.383 0 0"/>
       
    </worldbody>

    <actuator>
        <position ctrllimited="true" ctrlrange="-1 1" joint="r_close" kp="400"  user="1"/>
        <position ctrllimited="true" ctrlrange="-1 1" joint="l_close" kp="400"  user="1"/>
    </actuator>
</mujoco>
